Workbook

Sheet Описание
A1: Управление рисками. Оценка валютного риска (VaR)
A2: Выполнил: Кокотанов
A3: Актив: евро (курс EUR/USD, долл. США за 1 евро). Период: до / после кризиса 2008 г.
A4: Источник данных: официальные ежедневные курсы Европейского центрального банка (ECB euro reference rates), https://www.ecb.europa.eu/stats/eurofxref/
A6: Параметры расчёта (жёлтые ячейки можно менять — все расчёты пересчитаются)
A7: Стоимость позиции P, долл. США | B7: 1000000
A8: Квантиль α для 95% | B8: 1.645
A9: Квантиль α для 99% | B9: 2.326
A10: Горизонт t, дней (короткий) | B10: 1
A11: Горизонт t, дней (длинный) | B11: 10
A12: Окно скользящего σ, дней | B12: 60
A13: λ (EWMA, RiskMetrics) | B13: 0.94
A15: Этапы работы (по диаграмме вариационно-ковариационного анализа)
A16: 1. Рыночные данные | B16: Лист «Данные»: ежедневный курс EUR/USD 02.01.2006–31.12.2009 (1022 наблюдений). Период «До» – 2006–2007 гг. (510 дн.), «После» – 2008–2009 гг. (512 дн.); частота – дневная, без взвешивания (дополнительно – экспоненциальное взвешивание EWMA).
A17: 2. Доходность | B17: Лист «Данные»: процентная доходность r = Pt / Pt-1 − 1 и логарифмическая ln(Pt / Pt-1).
A18: 3. Тест: графики, стд. откл./дисперсия | B18: Лист «Статистика»: среднее, дисперсия, стандартное отклонение (волатильность), асимметрия, эксцесс по периодам, частотные распределения; лист «Графики»: динамика курса, распределение курса, распределение доходности.
A19: 4. VaR | B19: Лист «VaR»: параметрический VaR = α · σ · P · √t для 95% и 99%, сравнение с историческим VaR; динамика VaR (скользящее окно и EWMA) – на листе «Графики».
A21: Выводы
A22: 1. В 2006–2007 гг. евро плавно укреплялся (с ~1,18 до ~1,49 $ за €), дневная волатильность составляла 0,45% (≈7,1% годовых).
A23: 2. После начала кризиса 2008 г. курс стал резко колебаться (пик 1,60 в июле 2008 г., падение до 1,25 в октябре 2008 г.); стандартное отклонение доходности выросло до 0,85% в день (≈13,5% годовых), т.е. в 1,9 раза, дисперсия – в 3,6 раза.
A24: 3. Параметрический VaR 99% позиции 1 млн $ на 1 день вырос с ≈10 438 $ до ≈19 817 $; максимальный дневной убыток вырос с 1,19% до 4,63%.
A25: 4. Распределение доходности после 2008 г. имеет «тяжёлые хвосты» (эксцесс > 3): исторический VaR 99% выше параметрического, т.е. допущение о нормальности занижает риск в кризис: бэктест показал 10 дней с убытком больше VaR 99% из 512 при ожидаемых ≈5. Модель EWMA быстрее реагирует на рост волатильности, чем простое скользящее окно.
A26: 5. Валютный риск евро в кризисный период вырос примерно вдвое – при оценке VaR необходимо учитывать смену режима рынка (выбор периода анализа) и использовать взвешивание данных.

Sheet Данные
A1: Дата | B1: Курс EUR/USD | C1: Период | D1: Доходность r, % | E1: Лог. доходность | F1: Скользящее σ | G1: σ EWMA | H1: VaR 99% (скольз. σ), $ | I1: VaR 99% (EWMA), $
A2: 38719 | B2: 1.1826 | C2: До
A3: 38720 | B3: 1.1875 | C3: До | D3: =B3/B2-1 | E3: =LN(B3/B2)
A4: 38721 | B4: 1.2083 | C4: До | D4: =B4/B3-1 | E4: =LN(B4/B3)
A5: 38722 | B5: 1.2088 | C5: До | D5: =B5/B4-1 | E5: =LN(B5/B4)
A6: 38723 | B6: 1.2093 | C6: До | D6: =B6/B5-1 | E6: =LN(B6/B5)
A7: 38726 | B7: 1.2078 | C7: До | D7: =B7/B6-1 | E7: =LN(B7/B6)
A8: 38727 | B8: 1.2064 | C8: До | D8: =B8/B7-1 | E8: =LN(B8/B7)
A9: 38728 | B9: 1.2088 | C9: До | D9: =B9/B8-1 | E9: =LN(B9/B8)
A10: 38729 | B10: 1.2113 | C10: До | D10: =B10/B9-1 | E10: =LN(B10/B9)
A11: 38730 | B11: 1.2039 | C11: До | D11: =B11/B10-1 | E11: =LN(B11/B10)
A12: 38733 | B12: 1.2112 | C12: До | D12: =B12/B11-1 | E12: =LN(B12/B11)
A13: 38734 | B13: 1.2075 | C13: До | D13: =B13/B12-1 | E13: =LN(B13/B12)
A14: 38735 | B14: 1.2125 | C14: До | D14: =B14/B13-1 | E14: =LN(B14/B13)
... A22: 38747 | B22: 1.2082 | C22: До | D22: =B22/B21-1 | E22: =LN(B22/B21)
A23: 38748 | B23: 1.2118 | C23: До | D23: =B23/B22-1 | E23: =LN(B23/B22) | G23: =_xlfn.STDEV.S(D3:D22)
A24: 38749 | B24: 1.2092 | C24: До | D24: =B24/B23-1 | E24: =LN(B24/B23) | G24: =SQRT(Описание!$B$13*G23^2+(1-Описание!$B$13)*D23^2)
A25: 38750 | B25: 1.2066 | C25: До | D25: =B25/B24-1 | E25: =LN(B25/B24) | G25: =SQRT(Описание!$B$13*G24^2+(1-Описание!$B$13)*D24^2)
A26: 38751 | B26: 1.2061 | C26: До | D26: =B26/B25-1 | E26: =LN(B26/B25) | G26: =SQRT(Описание!$B$13*G25^2+(1-Описание!$B$13)*D25^2)
A27: 38754 | B27: 1.1981 | C27: До | D27: =B27/B26-1 | E27: =LN(B27/B26) | G27: =SQRT(Описание!$B$13*G26^2+(1-Описание!$B$13)*D26^2)
A28: 38755 | B28: 1.1973 | C28: До | D28: =B28/B27-1 | E28: =LN(B28/B27) | G28: =SQRT(Описание!$B$13*G27^2+(1-Описание!$B$13)*D27^2)
A29: 38756 | B29: 1.1948 | C29: До | D29: =B29/B28-1 | E29: =LN(B29/B28) | G29: =SQRT(Описание!$B$13*G28^2+(1-Описание!$B$13)*D28^2)
A30: 38757 | B30: 1.1972 | C30: До | D30: =B30/B29-1 | E30: =LN(B30/B29) | G30: =SQRT(Описание!$B$13*G29^2+(1-Описание!$B$13)*D29^2)
A31: 38758 | B31: 1.197 | C31: До | D31: =B31/B30-1 | E31: =LN(B31/B30) | G31: =SQRT(Описание!$B$13*G30^2+(1-Описание!$B$13)*D30^2)
A32: 38761 | B32: 1.1888 | C32: До | D32: =B32/B31-1 | E32: =LN(B32/B31) | G32: =SQRT(Описание!$B$13*G31^2+(1-Описание!$B$13)*D31^2)
A33: 38762 | B33: 1.1898 | C33: До | D33: =B33/B32-1 | E33: =LN(B33/B32) | G33: =SQRT(Описание!$B$13*G32^2+(1-Описание!$B$13)*D32^2)
A34: 38763 | B34: 1.1904 | C34: До | D34: =B34/B33-1 | E34: =LN(B34/B33) | G34: =SQRT(Описание!$B$13*G33^2+(1-Описание!$B$13)*D33^2)
A35: 38764 | B35: 1.1858 | C35: До | D35: =B35/B34-1 | E35: =LN(B35/B34) | G35: =SQRT(Описание!$B$13*G34^2+(1-Описание!$B$13)*D34^2)
... A62: 38803 | B62: 1.2025 | C62: До | D62: =B62/B61-1 | E62: =LN(B62/B61) | G62: =SQRT(Описание!$B$13*G61^2+(1-Описание!$B$13)*D61^2)
A63: 38804 | B63: 1.2084 | C63: До | D63: =B63/B62-1 | E63: =LN(B63/B62) | F63: =_xlfn.STDEV.S(OFFSET(D63,-Описание!$B$12,0,Описание!$B$12,1)) | G63: =SQRT(Описание!$B$13*G62^2+(1-Описание!$B$13)*D62^2) | H63: =Описание!$B$9*F63*Описание!$B$7 | I63: =Описание!$B$9*G63*Описание!$B$7
A64: 38805 | B64: 1.2012 | C64: До | D64: =B64/B63-1 | E64: =LN(B64/B63) | F64: =_xlfn.STDEV.S(OFFSET(D64,-Описание!$B$12,0,Описание!$B$12,1)) | G64: =SQRT(Описание!$B$13*G63^2+(1-Описание!$B$13)*D63^2) | H64: =Описание!$B$9*F64*Описание!$B$7 | I64: =Описание!$B$9*G64*Описание!$B$7
A65: 38806 | B65: 1.2096 | C65: До | D65: =B65/B64-1 | E65: =LN(B65/B64) | F65: =_xlfn.STDEV.S(OFFSET(D65,-Описание!$B$12,0,Описание!$B$12,1)) | G65: =SQRT(Описание!$B$13*G64^2+(1-Описание!$B$13)*D64^2) | H65: =Описание!$B$9*F65*Описание!$B$7 | I65: =Описание!$B$9*G65*Описание!$B$7
A66: 38807 | B66: 1.2104 | C66: До | D66: =B66/B65-1 | E66: =LN(B66/B65) | F66: =_xlfn.STDEV.S(OFFSET(D66,-Описание!$B$12,0,Описание!$B$12,1)) | G66: =SQRT(Описание!$B$13*G65^2+(1-Описание!$B$13)*D65^2) | H66: =Описание!$B$9*F66*Описание!$B$7 | I66: =Описание!$B$9*G66*Описание!$B$7
A67: 38810 | B67: 1.2063 | C67: До | D67: =B67/B66-1 | E67: =LN(B67/B66) | F67: =_xlfn.STDEV.S(OFFSET(D67,-Описание!$B$12,0,Описание!$B$12,1)) | G67: =SQRT(Описание!$B$13*G66^2+(1-Описание!$B$13)*D66^2) | H67: =Описание!$B$9*F67*Описание!$B$7 | I67: =Описание!$B$9*G67*Описание!$B$7
A68: 38811 | B68: 1.2217 | C68: До | D68: =B68/B67-1 | E68: =LN(B68/B67) | F68: =_xlfn.STDEV.S(OFFSET(D68,-Описание!$B$12,0,Описание!$B$12,1)) | G68: =SQRT(Описание!$B$13*G67^2+(1-Описание!$B$13)*D67^2) | H68: =Описание!$B$9*F68*Описание!$B$7 | I68: =Описание!$B$9*G68*Описание!$B$7
A69: 38812 | B69: 1.2262 | C69: До | D69: =B69/B68-1 | E69: =LN(B69/B68) | F69: =_xlfn.STDEV.S(OFFSET(D69,-Описание!$B$12,0,Описание!$B$12,1)) | G69: =SQRT(Описание!$B$13*G68^2+(1-Описание!$B$13)*D68^2) | H69: =Описание!$B$9*F69*Описание!$B$7 | I69: =Описание!$B$9*G69*Описание!$B$7
A70: 38813 | B70: 1.2312 | C70: До | D70: =B70/B69-1 | E70: =LN(B70/B69) | F70: =_xlfn.STDEV.S(OFFSET(D70,-Описание!$B$12,0,Описание!$B$12,1)) | G70: =SQRT(Описание!$B$13*G69^2+(1-Описание!$B$13)*D69^2) | H70: =Описание!$B$9*F70*Описание!$B$7 | I70: =Описание!$B$9*G70*Описание!$B$7
A71: 38814 | B71: 1.2179 | C71: До | D71: =B71/B70-1 | E71: =LN(B71/B70) | F71: =_xlfn.STDEV.S(OFFSET(D71,-Описание!$B$12,0,Описание!$B$12,1)) | G71: =SQRT(Описание!$B$13*G70^2+(1-Описание!$B$13)*D70^2) | H71: =Описание!$B$9*F71*Описание!$B$7 | I71: =Описание!$B$9*G71*Описание!$B$7
A72: 38817 | B72: 1.2099 | C72: До | D72: =B72/B71-1 | E72: =LN(B72/B71) | F72: =_xlfn.STDEV.S(OFFSET(D72,-Описание!$B$12,0,Описание!$B$12,1)) | G72: =SQRT(Описание!$B$13*G71^2+(1-Описание!$B$13)*D71^2) | H72: =Описание!$B$9*F72*Описание!$B$7 | I72: =Описание!$B$9*G72*Описание!$B$7
A73: 38818 | B73: 1.2105 | C73: До | D73: =B73/B72-1 | E73: =LN(B73/B72) | F73: =_xlfn.STDEV.S(OFFSET(D73,-Описание!$B$12,0,Описание!$B$12,1)) | G73: =SQRT(Описание!$B$13*G72^2+(1-Описание!$B$13)*D72^2) | H73: =Описание!$B$9*F73*Описание!$B$7 | I73: =Описание!$B$9*G73*Описание!$B$7
...

Sheet Статистика
A1: Этап 3. Тест: статистические характеристики курса и доходности
A3: Показатель | B3: До (2006–2007) | C3: После (2008–2009) | D3: После / До
A4: Число наблюдений доходности | B4: =COUNT(Данные!$D$3:$D$511) | C4: =COUNT(Данные!$D$512:$D$1023)
A5: Средний курс, $ за € | B5: =AVERAGE(Данные!$B$2:$B$511) | C5: =AVERAGE(Данные!$B$512:$B$1023) | D5: =C5/B5
A6: Минимальный курс | B6: =MIN(Данные!$B$2:$B$511) | C6: =MIN(Данные!$B$512:$B$1023)
A7: Максимальный курс | B7: =MAX(Данные!$B$2:$B$511) | C7: =MAX(Данные!$B$512:$B$1023)
A8: Средняя дневная доходность | B8: =AVERAGE(Данные!$D$3:$D$511) | C8: =AVERAGE(Данные!$D$512:$D$1023)
A9: Дисперсия доходности | B9: =_xlfn.VAR.S(Данные!$D$3:$D$511) | C9: =_xlfn.VAR.S(Данные!$D$512:$D$1023) | D9: =C9/B9
A10: Стандартное отклонение σ (дневная волатильность) | B10: =_xlfn.STDEV.S(Данные!$D$3:$D$511) | C10: =_xlfn.STDEV.S(Данные!$D$512:$D$1023) | D10: =C10/B10
A11: Годовая волатильность σ·√250 | B11: =B10*SQRT(250) | C11: =C10*SQRT(250) | D11: =C11/B11
A12: Минимальная дневная доходность | B12: =MIN(Данные!$D$3:$D$511) | C12: =MIN(Данные!$D$512:$D$1023) | D12: =C12/B12
A13: Максимальная дневная доходность | B13: =MAX(Данные!$D$3:$D$511) | C13: =MAX(Данные!$D$512:$D$1023) | D13: =C13/B13
A14: Асимметрия | B14: =SKEW(Данные!$D$3:$D$511) | C14: =SKEW(Данные!$D$512:$D$1023)
A15: Эксцесс | B15: =KURT(Данные!$D$3:$D$511) | C15: =KURT(Данные!$D$512:$D$1023)
A18: Распределение частоты значений курса
A19: Интервал курса | B19: До, дней | C19: После, дней | D19: Всего
A20: 1.16–1.20 | B20: =COUNTIFS(Данные!$B$2:$B$511,">=1.16",Данные!$B$2:$B$511,"<1.2") | C20: =COUNTIFS(Данные!$B$512:$B$1023,">=1.16",Данные!$B$512:$B$1023,"<1.2") | D20: =B20+C20
A21: 1.20–1.24 | B21: =COUNTIFS(Данные!$B$2:$B$511,">=1.2",Данные!$B$2:$B$511,"<1.24") | C21: =COUNTIFS(Данные!$B$512:$B$1023,">=1.2",Данные!$B$512:$B$1023,"<1.24") | D21: =B21+C21
A22: 1.24–1.28 | B22: =COUNTIFS(Данные!$B$2:$B$511,">=1.24",Данные!$B$2:$B$511,"<1.28") | C22: =COUNTIFS(Данные!$B$512:$B$1023,">=1.24",Данные!$B$512:$B$1023,"<1.28") | D22: =B22+C22
A23: 1.28–1.32 | B23: =COUNTIFS(Данные!$B$2:$B$511,">=1.28",Данные!$B$2:$B$511,"<1.32") | C23: =COUNTIFS(Данные!$B$512:$B$1023,">=1.28",Данные!$B$512:$B$1023,"<1.32") | D23: =B23+C23
A24: 1.32–1.36 | B24: =COUNTIFS(Данные!$B$2:$B$511,">=1.32",Данные!$B$2:$B$511,"<1.36") | C24: =COUNTIFS(Данные!$B$512:$B$1023,">=1.32",Данные!$B$512:$B$1023,"<1.36") | D24: =B24+C24
A25: 1.36–1.40 | B25: =COUNTIFS(Данные!$B$2:$B$511,">=1.36",Данные!$B$2:$B$511,"<1.4") | C25: =COUNTIFS(Данные!$B$512:$B$1023,">=1.36",Данные!$B$512:$B$1023,"<1.4") | D25: =B25+C25
A26: 1.40–1.44 | B26: =COUNTIFS(Данные!$B$2:$B$511,">=1.4",Данные!$B$2:$B$511,"<1.44") | C26: =COUNTIFS(Данные!$B$512:$B$1023,">=1.4",Данные!$B$512:$B$1023,"<1.44") | D26: =B26+C26
A27: 1.44–1.48 | B27: =COUNTIFS(Данные!$B$2:$B$511,">=1.44",Данные!$B$2:$B$511,"<1.48") | C27: =COUNTIFS(Данные!$B$512:$B$1023,">=1.44",Данные!$B$512:$B$1023,"<1.48") | D27: =B27+C27
A28: 1.48–1.52 | B28: =COUNTIFS(Данные!$B$2:$B$511,">=1.48",Данные!$B$2:$B$511,"<1.52") | C28: =COUNTIFS(Данные!$B$512:$B$1023,">=1.48",Данные!$B$512:$B$1023,"<1.52") | D28: =B28+C28
A29: 1.52–1.56 | B29: =COUNTIFS(Данные!$B$2:$B$511,">=1.52",Данные!$B$2:$B$511,"<1.56") | C29: =COUNTIFS(Данные!$B$512:$B$1023,">=1.52",Данные!$B$512:$B$1023,"<1.56") | D29: =B29+C29
A30: 1.56–1.60 | B30: =COUNTIFS(Данные!$B$2:$B$511,">=1.56",Данные!$B$2:$B$511,"<1.6") | C30: =COUNTIFS(Данные!$B$512:$B$1023,">=1.56",Данные!$B$512:$B$1023,"<1.6") | D30: =B30+C30
A33: Распределение доходности (доля дней, %)
A34: Интервал доходности | B34: До, % | C34: После, % | D34: Нормальное (σ «До»), %
A35: < -2.5% | B35: =COUNTIFS(Данные!$D$3:$D$511,"<-0.025")/B4 | C35: =COUNTIFS(Данные!$D$512:$D$1023,"<-0.025")/C4 | D35: =_xlfn.NORM.DIST(-0.025,B8,B10,TRUE)
A36: -2.5…-2.0 | B36: =COUNTIFS(Данные!$D$3:$D$511,">=-0.025",Данные!$D$3:$D$511,"<-0.02")/B4 | C36: =COUNTIFS(Данные!$D$512:$D$1023,">=-0.025",Данные!$D$512:$D$1023,"<-0.02")/C4 | D36: =_xlfn.NORM.DIST(-0.02,B8,B10,TRUE)-_xlfn.NORM.DIST(-0.025,B8,B10,TRUE)
A37: -2.0…-1.5 | B37: =COUNTIFS(Данные!$D$3:$D$511,">=-0.02",Данные!$D$3:$D$511,"<-0.015")/B4 | C37: =COUNTIFS(Данные!$D$512:$D$1023,">=-0.02",Данные!$D$512:$D$1023,"<-0.015")/C4 | D37: =_xlfn.NORM.DIST(-0.015,B8,B10,TRUE)-_xlfn.NORM.DIST(-0.02,B8,B10,TRUE)
A38: -1.5…-1.0 | B38: =COUNTIFS(Данные!$D$3:$D$511,">=-0.015",Данные!$D$3:$D$511,"<-0.01")/B4 | C38: =COUNTIFS(Данные!$D$512:$D$1023,">=-0.015",Данные!$D$512:$D$1023,"<-0.01")/C4 | D38: =_xlfn.NORM.DIST(-0.01,B8,B10,TRUE)-_xlfn.NORM.DIST(-0.015,B8,B10,TRUE)
A39: -1.0…-0.5 | B39: =COUNTIFS(Данные!$D$3:$D$511,">=-0.01",Данные!$D$3:$D$511,"<-0.005")/B4 | C39: =COUNTIFS(Данные!$D$512:$D$1023,">=-0.01",Данные!$D$512:$D$1023,"<-0.005")/C4 | D39: =_xlfn.NORM.DIST(-0.005,B8,B10,TRUE)-_xlfn.NORM.DIST(-0.01,B8,B10,TRUE)
A40: -0.5…0.0 | B40: =COUNTIFS(Данные!$D$3:$D$511,">=-0.005",Данные!$D$3:$D$511,"<0.0")/B4 | C40: =COUNTIFS(Данные!$D$512:$D$1023,">=-0.005",Данные!$D$512:$D$1023,"<0.0")/C4 | D40: =_xlfn.NORM.DIST(0.0,B8,B10,TRUE)-_xlfn.NORM.DIST(-0.005,B8,B10,TRUE)
A41: 0.0…0.5 | B41: =COUNTIFS(Данные!$D$3:$D$511,">=0.0",Данные!$D$3:$D$511,"<0.005")/B4 | C41: =COUNTIFS(Данные!$D$512:$D$1023,">=0.0",Данные!$D$512:$D$1023,"<0.005")/C4 | D41: =_xlfn.NORM.DIST(0.005,B8,B10,TRUE)-_xlfn.NORM.DIST(0.0,B8,B10,TRUE)
A42: 0.5…1.0 | B42: =COUNTIFS(Данные!$D$3:$D$511,">=0.005",Данные!$D$3:$D$511,"<0.01")/B4 | C42: =COUNTIFS(Данные!$D$512:$D$1023,">=0.005",Данные!$D$512:$D$1023,"<0.01")/C4 | D42: =_xlfn.NORM.DIST(0.01,B8,B10,TRUE)-_xlfn.NORM.DIST(0.005,B8,B10,TRUE)
A43: 1.0…1.5 | B43: =COUNTIFS(Данные!$D$3:$D$511,">=0.01",Данные!$D$3:$D$511,"<0.015")/B4 | C43: =COUNTIFS(Данные!$D$512:$D$1023,">=0.01",Данные!$D$512:$D$1023,"<0.015")/C4 | D43: =_xlfn.NORM.DIST(0.015,B8,B10,TRUE)-_xlfn.NORM.DIST(0.01,B8,B10,TRUE)
A44: 1.5…2.0 | B44: =COUNTIFS(Данные!$D$3:$D$511,">=0.015",Данные!$D$3:$D$511,"<0.02")/B4 | C44: =COUNTIFS(Данные!$D$512:$D$1023,">=0.015",Данные!$D$512:$D$1023,"<0.02")/C4 | D44: =_xlfn.NORM.DIST(0.02,B8,B10,TRUE)-_xlfn.NORM.DIST(0.015,B8,B10,TRUE)
A45: 2.0…2.5 | B45: =COUNTIFS(Данные!$D$3:$D$511,">=0.02",Данные!$D$3:$D$511,"<0.025")/B4 | C45: =COUNTIFS(Данные!$D$512:$D$1023,">=0.02",Данные!$D$512:$D$1023,"<0.025")/C4 | D45: =_xlfn.NORM.DIST(0.025,B8,B10,TRUE)-_xlfn.NORM.DIST(0.02,B8,B10,TRUE)
...

Sheet VaR
A1: Этап 4. Value-at-Risk длинной позиции в евро: VaR = α · σ · P · √t
A2: P – стоимость позиции, σ – стандартное отклонение дневной доходности, t – горизонт (дней), α – квантиль нормального распределения
A4: Метод / уровень доверия / горизонт | B4: До (2006–2007), $ | C4: После (2008–2009), $ | D4: После / До
A5: Параметрический VaR 95%, 1 день | B5: =Описание!$B$8*Статистика!B10*Описание!$B$7*SQRT(Описание!$B$10) | C5: =Описание!$B$8*Статистика!C10*Описание!$B$7*SQRT(Описание!$B$10) | D5: =C5/B5
A6: Параметрический VaR 99%, 1 день | B6: =Описание!$B$9*Статистика!B10*Описание!$B$7*SQRT(Описание!$B$10) | C6: =Описание!$B$9*Статистика!C10*Описание!$B$7*SQRT(Описание!$B$10) | D6: =C6/B6
A7: Параметрический VaR 95%, 10 дней | B7: =Описание!$B$8*Статистика!B10*Описание!$B$7*SQRT(Описание!$B$11) | C7: =Описание!$B$8*Статистика!C10*Описание!$B$7*SQRT(Описание!$B$11) | D7: =C7/B7
A8: Параметрический VaR 99%, 10 дней | B8: =Описание!$B$9*Статистика!B10*Описание!$B$7*SQRT(Описание!$B$11) | C8: =Описание!$B$9*Статистика!C10*Описание!$B$7*SQRT(Описание!$B$11) | D8: =C8/B8
A9: Исторический VaR 95%, 1 день | B9: =-_xlfn.PERCENTILE.INC(Данные!$D$3:$D$511,0.05)*Описание!$B$7 | C9: =-_xlfn.PERCENTILE.INC(Данные!$D$512:$D$1023,0.05)*Описание!$B$7 | D9: =C9/B9
A10: Исторический VaR 99%, 1 день | B10: =-_xlfn.PERCENTILE.INC(Данные!$D$3:$D$511,0.01)*Описание!$B$7 | C10: =-_xlfn.PERCENTILE.INC(Данные!$D$512:$D$1023,0.01)*Описание!$B$7 | D10: =C10/B10
A11: Максимальный фактический убыток за 1 день | B11: =-MIN(Данные!$D$3:$D$511)*Описание!$B$7 | C11: =-MIN(Данные!$D$512:$D$1023)*Описание!$B$7 | D11: =C11/B11
A13: Бэктест VaR 99% (1 день): число дней, когда убыток превысил VaR
A14: Показатель | B14: До | C14: После
A15: Дней с убытком > VaR 99% | B15: =COUNTIF(Данные!$D$3:$D$511,"<"&-B6/Описание!$B$7) | C15: =COUNTIF(Данные!$D$512:$D$1023,"<"&-C6/Описание!$B$7)
A16: Ожидаемое число (1% наблюдений) | B16: =0.01*Статистика!B4 | C16: =0.01*Статистика!C4
A19: Данные для графика VaR (1 день)
B20: До (2006–2007) | C20: После (2008–2009)
A21: Параметр. 95% | B21: =B5 | C21: =C5
A22: Параметр. 99% | B22: =B6 | C22: =C6
A23: Историч. 95% | B23: =B9 | C23: =C9
A24: Историч. 99% | B24: =B10 | C24: =C10

Sheet Графики
A1: Графики: курс → распределение курса → распределение доходности → VaR
